यहाँ एक कोड है जो `finally` क्लॉज़ के साथ अपवाद प्रबंधन को दर्शाता है:

```python
# Finally() क्लॉज़ के साथ अपवाद प्रबंधन का उदाहरण
#
# @author SunilOS  
# @version 1.0
# @Copyright (c) SunilOS  
# @Url www.SunilOs.com
#

def hello():
    try:
        return 1
    finally:
        return 2

k = hello()
print(k)  # Finally ब्लॉक तब भी कार्यान्वित होता है जब try ब्लॉक में एक return स्टेटमेंट होता है।
```

### व्याख्या:
- **`try` ब्लॉक**:
  - इसमें एक `return` स्टेटमेंट है जो `1` लौटाने की कोशिश करता है।

- **`finally` ब्लॉक**:
  - `try` ब्लॉक के बाद कार्यान्वित होता है, चाहे कोई अपवाद उत्पन्न हो या न हो।
  - इसमें एक `return` स्टेटमेंट है जो `2` लौटाने की कोशिश करता है।

- **परिणाम**:
  - `finally` ब्लॉक `try` ब्लॉक से लौटाए गए मान को ओवरराइड कर देता है, इसलिए `hello()` फ़ंक्शन `2` लौटाता है।

`finally` ब्लॉक हमेशा कार्यान्वित होता है, जो कि सफाई संचालन या यह सुनिश्चित करने के लिए उपयोगी हो सकता है कि कुछ कोड `try` ब्लॉक के परिणाम के बावजूद चले।
