यहाँ एक कोड है जो `ValueError` को `try` ब्लॉक के साथ और `while` लूप में संभालने को दर्शाता है:

```python
# ValueError के साथ Try Except का उदाहरण  
# 
# @author SunilOS  
# @version 1.0
# @Copyright (c) SunilOS  
# @Url www.SunilOs.com
#  

while True:  
    try:
        x = int(input("कृपया एक संख्या दर्ज करें: "))
        print("%s का पाँचवाँ घातांक %s है" % (x, x**5))
    except ValueError:
        print("कृपया एक मान्य संख्या दर्ज करें!")
```

### व्याख्या:
- **`while True:`**: यह एक अनंत लूप बनाता है, जिससे उपयोगकर्ता बार-बार संख्याएँ दर्ज कर सकता है जब तक कि वे मान्य इनपुट नहीं देते या प्रोग्राम बंद नहीं होता।

- **`try` ब्लॉक**:
  - उपयोगकर्ता के इनपुट को एक पूर्णांक में बदलने की कोशिश करता है।
  - यदि सफल होता है, तो यह संख्या को 5 की शक्ति पर उठाने का परिणाम प्रिंट करता है।

- **`except ValueError`**:
  - उस स्थिति को संभालता है जब उपयोगकर्ता का इनपुट पूर्णांक में परिवर्तित नहीं हो सकता (जैसे, यदि उपयोगकर्ता ने गैर-सांख्यिकीय पाठ दर्ज किया हो)।
  - एक त्रुटि संदेश प्रिंट करता है जो उपयोगकर्ता से एक मान्य संख्या दर्ज करने के लिए कहता है।

लूप तब तक चलता रहेगा जब तक उपयोगकर्ता मान्य इनपुट नहीं प्रदान करता।
